2022-09-11 23:04:08,189 - exc_logger_2022_09_11.log - ERROR - exception in run_exception
=============
Traceback (most recent call last):
  File "/Users/pro/Documents/proj_data/demo_exception/logging_dec.py", line 36, in wrapper
    return func(*args, **kwargs)
  File "/Users/pro/Documents/proj_data/demo_exception/main.py", line 44, in run_exception
    check_exception(input_value)
  File "/Users/pro/Documents/proj_data/demo_exception/main.py", line 38, in check_exception
    raise NotGoodError(f"You have input a negative value {input_value}")
NotGoodError: You have input a negative value -9
